assert.js:*
    throw newErr;
    ^

AssertionError [ERR_ASSERTION]: ifError got unwanted exception: test error
   at z (*if-error-has-good-stack.js:*:*
   at y (*if-error-has-good-stack.js:*:*)
   at x (*if-error-has-good-stack.js:*:*)
   at Anonymous function (*if-error-has-good-stack.js:*:*)
   at c (*if-error-has-good-stack.js:*:*)
   at b (*if-error-has-good-stack.js:*:*)
   at a (*if-error-has-good-stack.js:*:*)
   at Anonymous function (*if-error-has-good-stack.js:*:*)
   at Module.prototype._compile (internal/modules/cjs/loader.js:*:*)
   at Module._extensions[.js] (internal/modules/cjs/loader.js:*:*)
   at Module.prototype.load (internal/modules/cjs/loader.js:*:*)
   at tryModuleLoad (internal/modules/cjs/loader.js:*:*)
   at Module._load (internal/modules/cjs/loader.js:*:*)
   at Module.runMain (internal/modules/cjs/loader.js:*:*)